Workbook

Sheet WEEKLY SALES REPORT MAR  20 (2
A1: DATE: | B1: 1.3.2025 - 31.3.2025
A2: Product category | B2: Week 1 | C2: week 2 | D2: Week 3 | E2: Week 4 | F2: Week 5 | G2: TOTAL
A3: Non Alcholic | B3: 866000 | C3: 1166000 | D3: 977000 | E3: 1436500 | F3: 562000 | G3: =SUM(B3:F3) -> 5007500
A4: Alcoholic | B4: 493000 | C4: 512000 | D4: 649000 | E4: 539000 | F4: 475000 | G4: =SUM(B4:F4) -> 2668000
A5: Fresh Products | B5: 712000 | C5: 534000 | D5: 685000 | E5: 630500 | F5: 264000 | G5: =SUM(B5:F5) -> 2825500
A6: Ice creams | B6: 168000 | C6: 104000 | D6: 96000 | E6: 119500 | F6: 59000 | G6: =SUM(B6:F6) -> 546500
A7: Confectionery | B7: 746100 | C7: 654000 | D7: 711500 | E7: 713500 | F7: 256300 | G7: =SUM(B7:F7) -> 3081400
A8: Tobacco | B8: 36000 | C8: 48000 | D8: 105000 | E8: 43000 | F8: 98000 | G8: =SUM(B8:F8) -> 330000
A9: Grocery | B9: 648000 | C9: 522000 | D9: 574000 | E9: 651000 | F9: 206000 | G9: =SUM(B9:F9) -> 2601000
A10: Health & beauty | B10: 295000 | C10: 287000 | D10: 475000 | E10: 463000 | F10: 200000 | G10: =SUM(B10:F10) -> 1720000
A11: Bazaar | B11: 54000 | C11: 38000 | D11: 42000 | E11: 60000 | F11: 31000 | G11: =SUM(B11:F11) -> 225000
A12: Car Care | G12: =SUM(B12:E12) -> 0
A13: Car wash | G13: =SUM(B13:E13) -> 0
A14: Press | G14: =SUM(B14:E14) -> 0
A15: Lottery | G15: =SUM(B15:E15) -> 0
A16: Coffee | B16: 25000 | C16: 6000 | D16: 11000 | E16: 16000 | F16: 7000 | G16: =SUM(B16:F16) -> 65000
A17: Snacks | G17: =SUM(B17:E17) -> 0
A18: Lubricants in shop | G18: =SUM(B18:E18) -> 0
A19: Guichet unique | G19: =SUM(B19:E19) -> 0
A20: Total | B20: =SUM(B3:B19) -> 4043100 | C20: =SUM(C3:C19) -> 3871000 | D20: =SUM(D3:D19) -> 4325500 | E20: =SUM(E3:E19) -> 4672000 | F20: =SUM(F3:F19) -> 2158300 | G20: =SUM(G3:G19) -> 19069900
A23: Maintenance Issues & Challenges
A24: The shop prfomance has not been good due fasting season but we hope to improve.thank you.

Sheet DAILY  SALES REPORT MAR.202 (2
B1: TotalEnergies MARKETING UGANDA LIMITED
B2: SHOP WEEKLY REPORT (MTD)
B3: SHOP NAME | C3: TotalEnergies RWIZI | G3: March.2025
B4: MONTH
A5: DATE | B5: Non Alcholic | C5: Alcoholic | D5: Fresh products | E5: Ice cream | F5: Confectionery | G5: Tobacco | H5: Grocery | I5: Health & beauty | J5: Bazaar | K5: Car Care | L5: Car wash | M5: Press | N5: Lottery | O5: Coffee | P5: Snacks | Q5: Lubricants in shop | R5: Guichet | S5: Total T/O (Excluding Airtime, carwash,lubricants in shop) | T5: Global Total | U5: GUICHET BANKING
A6: 1st | B6: 161000 | C6: 146000 | D6: 121000 | E6: 22000 | F6: 131000 | G6: 0 | H6: 106000 | I6: 30000 | J6: 0 | O6: 12000 | Q6: 0 | R6: 0 | T6: =SUM(B6:S6) -> 729000
A7: 2nd | B7: 133000 | C7: 44000 | D7: 109000 | E7: 28000 | F7: 103400 | G7: 12000 | H7: 92000 | I7: 38000 | J7: 6000 | O7: 0 | Q7: 0 | R7: 0 | T7: =SUM(B7:S7) -> 565400
A8: 3rd | B8: 113000 | C8: 36000 | D8: 70000 | E8: 16000 | F8: 103000 | G8: 24000 | H8: 79000 | I8: 52000 | J8: 20000 | O8: 0 | Q8: 0 | R8: 2000 | T8: =SUM(B8:S8) -> 515000
A9: 4th | B9: 121000 | C9: 17000 | D9: 113000 | E9: 10000 | F9: 109000 | G9: 0 | H9: 112000 | I9: 35000 | J9: 13000 | O9: 0 | Q9: 0 | R9: 262000 | T9: =SUM(B9:S9) -> 792000
A10: 5th | B10: 103000 | C10: 55000 | D10: 80000 | E10: 22000 | F10: 105000 | G10: 0 | H10: 57000 | I10: 42000 | J10: 12000 | O10: 5000 | Q10: 0 | R10: 126000 | T10: =SUM(B10:S10) -> 607000
A11: 6th | B11: 132000 | C11: 34000 | D11: 116000 | E11: 25000 | F11: 115700 | G11: 0 | H11: 117000 | I11: 51000 | J11: 3000 | O11: 0 | Q11: 0 | R11: 765000 | T11: =SUM(B11:S11) -> 1358700 | U11: 1000000
A12: 7th | B12: 103000 | C12: 161000 | D12: 103000 | E12: 45000 | F12: 79000 | G12: 0 | H12: 85000 | I12: 47000 | J12: 0 | O12: 0 | Q12: 0 | R12: 4000 | T12: =SUM(B12:S12) -> 627000
A13: 8th | B13: 135000 | C13: 52000 | D13: 136000 | E13: 16000 | F13: 107500 | G13: 0 | H13: 105000 | I13: 51000 | J13: 6000 | O13: 0 | Q13: 195500 | R13: 150000 | T13: =SUM(B13:S13) -> 954000
A14: 9th | B14: 119000 | C14: 151000 | D14: 72000 | E14: 0 | F14: 101000 | G14: 0 | H14: 92000 | I14: 6000 | J14: 4000 | O14: 11000 | Q14: 155000 | R14: 150000 | T14: =SUM(B14:S14) -> 861000
A15: 10th | B15: 224500 | C15: 96000 | D15: 63000 | E15: 20500 | F15: 93000 | G15: 24000 | H15: 82000 | I15: 41000 | J15: 6000 | O15: 0 | Q15: 119000 | R15: 123000 | T15: =SUM(B15:S15) -> 892000
A16: 11th | B16: 153000 | C16: 29000 | D16: 62000 | E16: 15000 | F16: 56800 | G16: 0 | H16: 44000 | I16: 35000 | J16: 6000 | O16: 0 | Q16: 102500 | R16: 0 | T16: =SUM(B16:S16) -> 503300
A17: 12th | B17: 177500 | C17: 90000 | D17: 62000 | E17: 7500 | F17: 93000 | G17: 0 | H17: 76000 | I17: 63000 | J17: 0 | O17: 0 | Q17: 195500 | R17: 0 | T17: =SUM(B17:S17) -> 764500
A18: 13th | B18: 164000 | C18: 42000 | D18: 76000 | E18: 30000 | F18: 51700 | G18: 0 | H18: 82000 | I18: 41000 | J18: 0 | O18: 0 | Q18: 119500 | R18: 13000 | T18: =SUM(B18:S18) -> 619200
A19: 14th | B19: 193000 | C19: 52000 | D19: 63000 | E19: 15000 | F19: 142000 | G19: 24000 | H19: 41000 | I19: 50000 | J19: 16000 | O19: 0 | Q19: 156000 | R19: 225000 | T19: =SUM(B19:S19) -> 977000
A20: 15th | B20: 200000 | C20: 100000 | D20: 98000 | E20: 15000 | F20: 72000 | G20: 24000 | H20: 107000 | I20: 74000 | J20: 17000 | O20: 12000 | Q20: 23000 | R20: 0 | T20: =SUM(B20:S20) -> 742000
A21: 16TH | B21: 112000 | C21: 50000 | D21: 79000 | E21: 11000 | F21: 117000 | G21: 12000 | H21: 74000 | I21: 64000 | J21: 3000 | O21: 0 | Q21: 78000 | R21: 0 | T21: =SUM(B21:S21) -> 600000
A22: 17th | B22: 113000 | C22: 169000 | D22: 113000 | E22: 19000 | F22: 117500 | G22: 12000 | H22: 80000 | I22: 51000 | J22: 3000 | O22: 0 | Q22: 215500 | R22: 0 | T22: =SUM(B22:S22) -> 893000
A23: 18th | B23: 109000 | C23: 118000 | D23: 82000 | E23: 8500 | F23: 86000 | G23: 18000 | H23: 49000 | I23: 67000 | J23: 4000 | O23: 7000 | Q23: 23000 | R23: 60000 | T23: =SUM(B23:S23) -> 631500
... A34: 29th | B34: 251000 | C34: 302000 | D34: 67000 | E34: 16000 | F34: 92600 | G34: 16000 | H34: 62000 | I34: 94000 | J34: 13000 | O34: 0 | Q34: 41000 | R34: 24000 | T34: =SUM(B34:S34) -> 978600
A35: 30TH | B35: 170000 | C35: 75000 | D35: 81000 | E35: 15000 | F35: 60000 | G35: 12000 | H35: 61000 | I35: 31000 | J35: 0 | O35: 0 | Q35: 0 | R35: 2962000 | T35: =SUM(B35:S35) -> 3467000 | U35: 2000000
A36: 31ST | B36: 141000 | C36: 109000 | D36: 116000 | E36: 28000 | F36: 103700 | G36: 70000 | H36: 83000 | I36: 75000 | J36: 18000 | O36: 0 | Q36: 0 | R36: 11000 | T36: =SUM(B36:S36) -> 754700
A37: GRAND TOTAL | B37: =SUM(B6:B36) -> 5007500 | C37: =SUM(C6:C36) -> 2679000 | D37: =SUM(D6:D36) -> 2825500 | E37: =SUM(E6:E36) -> 546500 | F37: =SUM(F6:F36) -> 3072400 | G37: =SUM(G6:G36) -> 327000 | H37: =SUM(H6:H36) -> 2601000 | I37: =SUM(I6:I36) -> 1720000 | J37: =SUM(J6:J36) -> 225000 | O37: =SUM(O6:O36) -> 65000 | Q37: =SUM(Q6:Q36) -> 1816500 | R37: =SUM(R6:R36) -> 9913000 | T37: =SUM(B37:S37) -> 30798400

Sheet Daily sales JULY 2023
B1: TotalEnergies MARKETING UGANDA LIMITED
B2: SHOP WEEKLY REPORT (MTD)
B3: SHOP NAME | C3: TotalEnergies RWIZI
B4: MONTH | C4: 45108
A5: DATE | B5: Non Alcholic | C5: Alcoholic | D5: Fresh products | E5: Ice cream | F5: Confectionery | G5: Tobacco | H5: Grocery | I5: Health & beauty | J5: Bazaar | K5: Car Care | L5: Car wash | M5: Press | N5: Lottery | O5: Coffee | P5: Snacks | Q5: Lubricants in shop | R5: Guichet | S5: Total T/O (Excluding Airtime, carwash,lubricants in shop) | T5: Global Total
A6: 1st | B6: 231000 | C6: 85000 | D6: 69000 | E6: 11000 | F6: 201000 | H6: 71000 | I6: 42000 | J6: 10000 | K6: 0 | O6: 0 | S6: =(B6+C6+D6+E6+F6+G6+H6+I6+J6+K6+M6+N6+O6+P6) -> 720000 | T6: =SUM(B6:R6) -> 720000
A7: 2nd | B7: 218500 | C7: 176000 | D7: 131000 | E7: 45500 | F7: 166000 | H7: 63000 | I7: 69500 | J7: 25000 | K7: 0 | O7: 0 | S7: =(B7+C7+D7+E7+F7+G7+H7+I7+J7+K7+M7+N7+O7+P7) -> 894500 | T7: =SUM(B7:R7) -> 894500
A8: 3rd | B8: 227500 | C8: 40000 | D8: 134000 | E8: 22500 | F8: 175500 | H8: 47000 | I8: 33500 | J8: 4000 | K8: 0 | O8: 0 | R8: 604000 | S8: =(B8+C8+D8+E8+F8+G8+H8+I8+J8+K8+M8+N8+O8+P8) -> 684000 | T8: =SUM(B8:R8) -> 1288000
A9: 4th | B9: 258000 | C9: 39000 | D9: 67500 | E9: 10000 | F9: 95500 | H9: 30000 | I9: 5000 | J9: 17000 | K9: 0 | O9: 0 | R9: 160000 | S9: =(B9+C9+D9+E9+F9+G9+H9+I9+J9+K9+M9+N9+O9+P9) -> 522000 | T9: =SUM(B9:R9) -> 682000
A10: 5th | B10: 313500 | C10: 96000 | D10: 121500 | E10: 16000 | F10: 88500 | H10: 114000 | I10: 56000 | J10: 31500 | K10: 0 | O10: 9000 | R10: 646000 | S10: =(B10+C10+D10+E10+F10+G10+H10+I10+J10+K10+M10+N10+O10+P10) -> 846000 | T10: =SUM(B10:R10) -> 1492000
A11: 6th | B11: 158000 | C11: 45000 | D11: 89000 | E11: 17000 | F11: 40000 | H11: 83000 | I11: 66000 | J11: 20000 | K11: 0 | O11: 5000 | R11: 302000 | S11: =(B11+C11+D11+E11+F11+G11+H11+I11+J11+K11+M11+N11+O11+P11) -> 523000 | T11: =SUM(B11:R11) -> 825000
A12: 7th | B12: 315000 | C12: 330000 | D12: 76500 | E12: 18000 | F12: 128500 | H12: 12000 | I12: 22500 | J12: 25500 | K12: 0 | O12: 19000 | R12: 1215000 | S12: =(B12+C12+D12+E12+F12+G12+H12+I12+J12+K12+M12+N12+O12+P12) -> 947000 | T12: =SUM(B12:R12) -> 2162000
A13: 8th | B13: 165500 | C13: 105000 | D13: 101000 | E13: 22000 | F13: 102500 | H13: 28000 | I13: 35000 | J13: 31000 | K13: 0 | O13: 35000 | R13: 0 | S13: =(B13+C13+D13+E13+F13+G13+H13+I13+J13+K13+M13+N13+O13+P13) -> 625000 | T13: =SUM(B13:R13) -> 625000
A14: 9th | B14: 198000 | C14: 8000 | D14: 85500 | E14: 32000 | F14: 121000 | H14: 12000 | I14: 18000 | J14: 5500 | K14: 0 | O14: 14000 | R14: 280000 | S14: =(B14+C14+D14+E14+F14+G14+H14+I14+J14+K14+M14+N14+O14+P14) -> 494000 | T14: =SUM(B14:R14) -> 774000
A15: 10th | B15: 276500 | C15: 144000 | D15: 133000 | E15: 15500 | F15: 123000 | H15: 66000 | I15: 6000 | J15: 34000 | K15: 0 | O15: 10000 | R15: 172000 | S15: =(B15+C15+D15+E15+F15+G15+H15+I15+J15+K15+M15+N15+O15+P15) -> 808000 | T15: =SUM(B15:R15) -> 980000
A16: 11th | B16: 265000 | C16: 166000 | D16: 159000 | E16: 52500 | F16: 135000 | H16: 95000 | I16: 123500 | J16: 5000 | K16: 0 | O16: 19000 | R16: 0 | S16: =(B16+C16+D16+E16+F16+G16+H16+I16+J16+K16+M16+N16+O16+P16) -> 1020000 | T16: =SUM(B16:R16) -> 1020000
A17: 12th | B17: 145000 | C17: 65000 | D17: 63000 | E17: 25000 | F17: 103000 | H17: 84000 | I17: 36000 | J17: 10000 | K17: 0 | O17: 0 | R17: -3400000 | S17: =(B17+C17+D17+E17+F17+G17+H17+I17+J17+K17+M17+N17+O17+P17) -> 531000 | T17: =SUM(B17:R17) -> -2869000 | U17: BANKING
A18: 13th | B18: 198500 | C18: 145000 | D18: 133500 | E18: 13000 | F18: 43000 | H18: 82000 | I18: 40000 | J18: 3500 | K18: 0 | O18: 8000 | R18: 0 | S18: =(B18+C18+D18+E18+F18+G18+H18+I18+J18+K18+M18+N18+O18+P18) -> 666500 | T18: =SUM(B18:R18) -> 666500
A19: 14th | B19: 166500 | C19: 210000 | D19: 147000 | E19: 9500 | F19: 140000 | H19: 47000 | I19: 37000 | J19: 5000 | K19: 0 | O19: 20000 | R19: 205000 | S19: =(B19+C19+D19+E19+F19+G19+H19+I19+J19+K19+M19+N19+O19+P19) -> 782000 | T19: =SUM(B19:R19) -> 987000
A20: 15th | B20: 403000 | C20: 560000 | D20: 202000 | E20: 30000 | F20: 279500 | H20: 401000 | I20: 71000 | J20: 3000 | K20: 0 | O20: 26000 | R20: 1205000 | S20: =(B20+C20+D20+E20+F20+G20+H20+I20+J20+K20+M20+N20+O20+P20) -> 1975500 | T20: =SUM(B20:R20) -> 3180500
A21: 16th | B21: 190000 | C21: 140000 | D21: 98000 | E21: 21000 | F21: 126000 | H21: 163000 | I21: 2000 | J21: 4000 | K21: 0 | O21: 16000 | R21: 0 | S21: =(B21+C21+D21+E21+F21+G21+H21+I21+J21+K21+M21+N21+O21+P21) -> 760000 | T21: =SUM(B21:R21) -> 760000
A22: 17th | B22: 221000 | C22: 82000 | D22: 118000 | E22: 40500 | F22: 50000 | H22: 54000 | I22: 50000 | J22: 12000 | K22: 0 | O22: 0 | R22: -1000000 | S22: =(B22+C22+D22+E22+F22+G22+H22+I22+J22+K22+M22+N22+O22+P22) -> 627500 | T22: =SUM(B22:R22) -> -372500 | U22: BANKING
A23: 18th | B23: 183000 | C23: 114000 | D23: 105000 | E23: 12000 | F23: 65000 | H23: 36000 | I23: 21000 | J23: 10000 | K23: 0 | O23: 0 | R23: -82000 | S23: =(B23+C23+D23+E23+F23+G23+H23+I23+J23+K23+M23+N23+O23+P23) -> 546000 | T23: =SUM(B23:R23) -> 464000
A24: 19th | B24: 130000 | C24: 77000 | D24: 71500 | E24: 11000 | F24: 62500 | H24: 47500 | I24: 50000 | J24: 6000 | K24: 0 | O24: 0 | R24: 190000 | S24: =(B24+C24+D24+E24+F24+G24+H24+I24+J24+K24+M24+N24+O24+P24) -> 455500 | T24: =SUM(B24:R24) -> 645500
A25: 20th | B25: 169000 | C25: 10000 | D25: 72000 | E25: 32000 | F25: 123000 | H25: 35000 | I25: 14000 | J25: 32000 | K25: 0 | O25: 12000 | R25: -24000 | S25: =(B25+C25+D25+E25+F25+G25+H25+I25+J25+K25+M25+N25+O25+P25) -> 499000 | T25: =SUM(B25:R25) -> 475000
A26: 21st | B26: 210000 | C26: 167000 | D26: 80000 | E26: 10000 | F26: 118500 | H26: 100000 | I26: 95000 | J26: 56000 | K26: 0 | O26: 15000 | R26: 0 | S26: =(B26+C26+D26+E26+F26+G26+H26+I26+J26+K26+M26+N26+O26+P26) -> 851500 | T26: =SUM(B26:R26) -> 851500
A27: 22nd | B27: 270000 | C27: 127000 | D27: 141000 | E27: 3000 | F27: 240300 | H27: 79000 | I27: 58000 | J27: 45000 | K27: 0 | O27: 8000 | R27: 46000 | S27: =(B27+C27+D27+E27+F27+G27+H27+I27+J27+K27+M27+N27+O27+P27) -> 971300 | T27: =SUM(B27:R27) -> 1017300
A28: 23rd | B28: 220000 | C28: 187000 | D28: 80000 | E28: 16500 | F28: 149500 | H28: 85000 | I28: 66000 | J28: 8000 | K28: 0 | O28: 24000 | R28: 424000 | S28: =(B28+C28+D28+E28+F28+G28+H28+I28+J28+K28+M28+N28+O28+P28) -> 836000 | T28: =SUM(B28:R28) -> 1260000
A29: 24th | B29: 319500 | C29: 104000 | D29: 125000 | E29: 9000 | F29: 75900 | H29: 45000 | I29: 35000 | J29: 6000 | K29: 0 | O29: 0 | R29: 882000 | S29: =(B29+C29+D29+E29+F29+G29+H29+I29+J29+K29+M29+N29+O29+P29) -> 719400 | T29: =SUM(B29:R29) -> 1601400
A30: 25th | B30: 286000 | C30: 111000 | D30: 131000 | E30: 3000 | F30: 84800 | H30: 21000 | I30: 10000 | J30: 5500 | K30: 0 | O30: 4000 | R30: 0 | S30: =(B30+C30+D30+E30+F30+G30+H30+I30+J30+K30+M30+N30+O30+P30) -> 656300 | T30: =SUM(B30:R30) -> 656300
A31: 26th | B31: 210000 | C31: 51000 | D31: 40000 | E31: 30000 | F31: 64000 | H31: 12000 | I31: 27000 | J31: 10000 | K31: 0 | O31: 0 | R31: 1459000 | S31: =(B31+C31+D31+E31+F31+G31+H31+I31+J31+K31+M31+N31+O31+P31) -> 444000 | T31: =SUM(B31:R31) -> 1903000
A32: 27th | B32: 267000 | C32: 276000 | D32: 141000 | E32: 10000 | F32: 121000 | H32: 94000 | I32: 130000 | J32: 11000 | K32: 0 | O32: 0 | R32: 0 | S32: =(B32+C32+D32+E32+F32+G32+H32+I32+J32+K32+M32+N32+O32+P32) -> 1050000 | T32: =SUM(B32:R32) -> 1050000
A33: 28th | B33: 276000 | C33: 78000 | D33: 110000 | E33: 26000 | F33: 85000 | H33: 70000 | I33: 71000 | J33: 42000 | K33: 0 | O33: 8000 | R33: 0 | S33: =(B33+C33+D33+E33+F33+G33+H33+I33+J33+K33+M33+N33+O33+P33) -> 766000 | T33: =SUM(B33:R33) -> 766000
A34: 29th | B34: 472000 | C34: 435000 | D34: 156000 | E34: 24000 | F34: 240000 | H34: 150000 | I34: 60000 | J34: 37000 | K34: 0 | O34: 28000 | R34: 0 | S34: =(B34+C34+D34+E34+F34+G34+H34+I34+J34+K34+M34+N34+O34+P34) -> 1602000 | T34: =SUM(B34:R34) -> 1602000
A35: 30th | B35: 210000 | C35: 70000 | D35: 105000 | E35: 42000 | F35: 151200 | H35: 78000 | I35: 75000 | J35: 20000 | K35: 0 | O35: 6000 | R35: 0 | S35: =(B35+C35+D35+E35+F35+G35+H35+I35+J35+K35+M35+N35+O35+P35) -> 757200 | T35: =SUM(B35:R35) -> 757200
A36: 31st | B36: 121000 | C36: 105000 | D36: 106000 | E36: 30000 | F36: 161500 | H36: 105000 | I36: 55000 | J36: 28000 | O36: 8000 | R36: -3244000 | S36: =SUM(B36:R36) -> -2524500 | T36: 711500 | U36: BANKING
A37: GRAND TOTAL | B37: =SUM(B6:B36) -> 7294000 | C37: =SUM(C6:C36) -> 4348000 | D37: =SUM(D6:D36) -> 3392000 | E37: =SUM(E6:E36) -> 659500 | F37: =SUM(F6:F36) -> 3860200 | G37: =SUM(G6:G36) -> 0 | H37: =SUM(H6:H36) -> 2409500 | I37: =SUM(I6:I36) -> 1480000 | ... T37: =SUM(T6:T36) -> 27575700

Sheet Weekly report JULY 2023
B2: TotalEnergies MARKETING UGANDA LIMITED
B3: SHOP WEEKLY REPORT (MTD)
B6: SHOP NAME | C6: TotalEnergies RWIZI
B8: DATE: | C8: 31.07.2023
B9: Product category | C9: Week 1 | D9: week 2 | E9: Week 3 | F9: Week 4 | G9: Week 5 | H9: TOTAL
A10: 1 | B10: Non Alcholic | C10: 1711500 | D10: 1355000 | E10: 1506000 | F10: 1848500 | G10: 803000 | H10: =SUM(C10:G10) -> 7224000
A11: 2 | B11: Alcoholic | C11: 910000 | D11: 843000 | E11: 1150000 | F11: 934000 | G11: 690000 | H11: =SUM(C11:G11) -> 4527000
A12: 3 | B12: Fresh Products | C12: 688500 | D12: 824000 | E12: 746500 | F12: 768000 | G12: 367000 | H12: =SUM(C12:G12) -> 3394000
A13: 4 | B13: Ice creams | C13: 140000 | D13: 159500 | E13: 145500 | F13: 97500 | G13: 66000 | H13: =SUM(C13:G13) -> 608500
A14: 5 | B14: Confectionery | C14: 792500 | D14: 767500 | E14: 796500 | F14: 781700 | G14: 552700 | H14: =SUM(C14:G14) -> 3690900
A15: 6 | B15: Tobacco | H15: =SUM(C15:F15) -> 0
A16: 7 | B16: Grocery | C16: 420000 | D16: 409000 | E16: 937000 | F16: 406000 | G16: 333000 | H16: =SUM(C16:G16) -> 2505000
A17: 8 | B17: Health & beauty | C17: 294500 | D17: 284500 | E17: 321000 | F17: 390000 | G17: 190000 | H17: =SUM(C17:G17) -> 1480000
A18: 9 | B18: Bazaar | C18: 140500 | D18: 105000 | E18: 117000 | F18: 155000 | G18: 83000 | H18: =SUM(C18:G18) -> 600500
A19: 10 | B19: Car Care | H19: =SUM(C19:F19) -> 0
A20: 11 | B20: Car wash | H20: =SUM(C20:F20) -> 0
A21: 12 | B21: Press | H21: =SUM(C21:F21) -> 0
A22: 13 | B22: Lottery | H22: =SUM(C22:F22) -> 0
A23: 14 | B23: Coffee | C23: 33000 | D23: 106000 | E23: 69000 | F23: 72000 | G23: 14000 | H23: =SUM(C23:G23) -> 294000
A24: 15 | B24: Snacks | H24: =SUM(C24:F24) -> 0
A25: 16 | B25: Lubricants in shop | H25: =SUM(C25:F25) -> 0
A26: 17 | B26: Guichet unique | H26: =SUM(C26:F26) -> 0
B27: Total | C27: =SUM(C10:C26) -> 5130500 | D27: =SUM(D10:D26) -> 4853500 | E27: =SUM(E10:E26) -> 5788500 | F27: =SUM(F10:F26) -> 5452700 | G27: =SUM(G10:G26) -> 3098700 | H27: =SUM(H10:H26) -> 24323900
B30: Maintenance Issues & Challenges
A31: 1
A32: 2
A33: 3
A34: 4
A35: 5
A36: 6

Sheet DAILY SALES AUGUST 2023
B1: TotalEnergies MARKETING UGANDA LIMITED
B2: SHOP WEEKLY REPORT (MTD)
B3: SHOP NAME | C3: TotalEnergies RWIZI
B4: MONTH | C4: 45139
A5: DATE | B5: Non Alcholic | C5: Alcoholic | D5: Fresh products | E5: Ice cream | F5: Confectionery | G5: Tobacco | H5: Grocery | I5: Health & beauty | J5: Bazaar | K5: Car Care | L5: Car wash | M5: Press | N5: Lottery | O5: Coffee | P5: Snacks | Q5: Lubricants in shop | R5: Guichet | S5: Total T/O (Excluding Airtime, carwash,lubricants in shop) | T5: Global Total
A6: 1st | B6: 171000 | C6: 26000 | D6: 41000 | E6: 19000 | F6: 94000 | G6: 0 | H6: 56000 | I6: 29000 | J6: 3000 | K6: 0 | O6: 0 | P6: 0 | Q6: 0 | S6: =(B6+C6+D6+E6+F6+G6+H6+I6+J6+K6+M6+N6+O6+P6) -> 439000 | T6: =SUM(B6:R6) -> 439000
A7: 2nd | B7: 154000 | C7: 87000 | D7: 89000 | E7: 17000 | F7: 84000 | G7: 0 | H7: 41000 | I7: 25000 | J7: 7000 | K7: 0 | O7: 42000 | S7: =(B7+C7+D7+E7+F7+G7+H7+I7+J7+K7+M7+N7+O7+P7) -> 546000 | T7: =SUM(B7:R7) -> 546000
A8: 3rd | B8: 156000 | C8: 74000 | D8: 104000 | E8: 15000 | F8: 118000 | H8: 29000 | I8: 60000 | J8: 4000 | K8: 0 | O8: 0 | R8: 1000 | S8: =(B8+C8+D8+E8+F8+G8+H8+I8+J8+K8+M8+N8+O8+P8) -> 560000 | T8: =SUM(B8:R8) -> 561000
A9: 4th | B9: 250000 | C9: 149000 | D9: 137000 | E9: 30000 | F9: 138500 | G9: 0 | H9: 204000 | I9: 110000 | J9: 7000 | K9: 0 | O9: 0 | R9: 2063000 | S9: =(B9+C9+D9+E9+F9+G9+H9+I9+J9+K9+M9+N9+O9+P9) -> 1025500 | T9: =SUM(B9:R9) -> 3088500
A10: 5th | B10: 346000 | C10: 391000 | D10: 175000 | E10: 19000 | F10: 190500 | H10: 38000 | I10: 27000 | J10: 15000 | K10: 0 | O10: 0 | R10: 2810000 | S10: =(B10+C10+D10+E10+F10+G10+H10+I10+J10+K10+M10+N10+O10+P10) -> 1201500 | T10: =SUM(B10:R10) -> 4011500
A11: 6th | B11: 301000 | C11: 36000 | D11: 260000 | E11: 153000 | F11: 38000 | G11: 96000 | H11: 41000 | I11: 12000 | J11: 23000 | K11: 0 | O11: 0 | R11: 397000 | S11: =(B11+C11+D11+E11+F11+G11+H11+I11+J11+K11+M11+N11+O11+P11) -> 960000 | T11: =SUM(B11:R11) -> 1357000
A12: 7th | B12: 258000 | C12: 125000 | D12: 92500 | E12: 5000 | F12: 134500 | H12: 18000 | I12: 73000 | J12: 4500 | K12: 0 | O12: 12000 | R12: 484000 | S12: =(B12+C12+D12+E12+F12+G12+H12+I12+J12+K12+M12+N12+O12+P12) -> 722500 | T12: =SUM(B12:R12) -> 1206500
A13: 8th | B13: 170000 | C13: 15000 | D13: 75000 | E13: 5000 | F13: 75000 | G13: 0 | H13: 51000 | I13: 35000 | J13: 7000 | K13: 0 | O13: 4000 | R13: 12000 | S13: =(B13+C13+D13+E13+F13+G13+H13+I13+J13+K13+M13+N13+O13+P13) -> 437000 | T13: =SUM(B13:R13) -> 449000
A14: 9th | B14: 192500 | C14: 39000 | D14: 69500 | E14: 4500 | F14: 73500 | G14: 12000 | H14: 79000 | I14: 85000 | J14: 9000 | K14: 0 | O14: 8000 | R14: 0 | S14: =(B14+C14+D14+E14+F14+G14+H14+I14+J14+K14+M14+N14+O14+P14) -> 572000 | T14: =SUM(B14:R14) -> 572000
A15: 10th | B15: 248000 | C15: 62000 | D15: 93000 | E15: 30000 | F15: 130000 | H15: 73000 | I15: 90000 | J15: 14000 | K15: 0 | O15: 13000 | R15: 0 | S15: =(B15+C15+D15+E15+F15+G15+H15+I15+J15+K15+M15+N15+O15+P15) -> 753000 | T15: =SUM(B15:R15) -> 753000
A16: 11th | B16: 262000 | C16: 260000 | D16: 85000 | E16: 30000 | F16: 141000 | H16: 70000 | I16: 95000 | J16: 20000 | K16: 0 | O16: 10000 | R16: 770000 | S16: =(B16+C16+D16+E16+F16+G16+H16+I16+J16+K16+M16+N16+O16+P16) -> 973000 | T16: =SUM(B16:R16) -> 1743000
A17: 12th | B17: 316000 | C17: 217000 | D17: 106000 | E17: 32000 | F17: 121000 | H17: 147000 | I17: 97000 | J17: 28000 | K17: 0 | O17: 30000 | R17: 1030000 | S17: =(B17+C17+D17+E17+F17+G17+H17+I17+J17+K17+M17+N17+O17+P17) -> 1094000 | T17: =SUM(B17:R17) -> 2124000 | U17: BANKING
A18: 13th | B18: 245000 | C18: 195000 | D18: 93000 | E18: 46000 | F18: 167000 | H18: 41000 | I18: 48000 | J18: 6000 | K18: 0 | O18: 22000 | R18: 1000000 | S18: =(B18+C18+D18+E18+F18+G18+H18+I18+J18+K18+M18+N18+O18+P18) -> 863000 | T18: =SUM(B18:R18) -> 1863000 | U18: BANKING
A19: 14th | B19: 259000 | C19: 106000 | D19: 113500 | E19: 30000 | F19: 101900 | G19: 6000 | H19: 48000 | I19: 64000 | J19: 5000 | K19: 0 | O19: 14000 | R19: 920000 | S19: =(B19+C19+D19+E19+F19+G19+H19+I19+J19+K19+M19+N19+O19+P19) -> 747400 | T19: =SUM(B19:R19) -> 1667400
A20: 15th | B20: 169500 | C20: 110000 | D20: 103500 | E20: 28000 | F20: 128500 | H20: 29000 | I20: 28500 | J20: 5000 | K20: 0 | O20: 4000 | R20: 0 | S20: =(B20+C20+D20+E20+F20+G20+H20+I20+J20+K20+M20+N20+O20+P20) -> 606000 | T20: =SUM(B20:R20) -> 606000
A21: 16TH | B21: 174000 | C21: 84000 | D21: 139500 | E21: 36000 | F21: 76500 | H21: 42000 | I21: 51000 | J21: 5000 | K21: 0 | O21: 4000 | R21: 3764000 | S21: =(B21+C21+D21+E21+F21+G21+H21+I21+J21+K21+M21+N21+O21+P21) -> 612000 | T21: =SUM(B21:R21) -> 4376000
A22: 17th | B22: 200000 | C22: 120000 | D22: 78000 | E22: 12000 | F22: 153000 | H22: 62000 | I22: 50000 | J22: 2000 | K22: 0 | O22: 0 | R22: 1709000 | S22: =(B22+C22+D22+E22+F22+G22+H22+I22+J22+K22+M22+N22+O22+P22) -> 677000 | T22: =SUM(B22:R22) -> 2386000 | U22: BANKING
A23: 18th | B23: 286500 | C23: 87000 | D23: 100000 | E23: 4500 | F23: 148000 | H23: 96000 | I23: 43000 | J23: 46000 | K23: 0 | O23: 16000 | R23: -11000 | S23: =(B23+C23+D23+E23+F23+G23+H23+I23+J23+K23+M23+N23+O23+P23) -> 827000 | T23: =SUM(B23:R23) -> 816000
A24: 19th | B24: 294500 | C24: 175000 | D24: 160000 | E24: 19500 | F24: 147500 | H24: 30000 | I24: 33000 | J24: 40300 | K24: 0 | O24: 19000 | R24: 140000 | S24: =(B24+C24+D24+E24+F24+G24+H24+I24+J24+K24+M24+N24+O24+P24) -> 918800 | T24: =SUM(B24:R24) -> 1058800
A25: 20th | B25: 317000 | C25: 100000 | D25: 134000 | E25: 20000 | F25: 202500 | H25: 71000 | I25: 30000 | J25: 10000 | K25: 0 | O25: 6000 | R25: 200000 | S25: =(B25+C25+D25+E25+F25+G25+H25+I25+J25+K25+M25+N25+O25+P25) -> 890500 | T25: =SUM(B25:R25) -> 1090500
A26: 21st | B26: 246000 | C26: 224000 | D26: 84000 | E26: 16000 | F26: 142500 | G26: 12000 | H26: 194000 | I26: 85000 | J26: 17000 | K26: 0 | O26: 0 | R26: 191000 | S26: =(B26+C26+D26+E26+F26+G26+H26+I26+J26+K26+M26+N26+O26+P26) -> 1020500 | T26: =SUM(B26:R26) -> 1211500
A27: 22nd | B27: 211000 | C27: 59000 | D27: 133000 | E27: 7500 | F27: 115500 | G27: 12000 | H27: 109500 | I27: 71000 | J27: 6000 | K27: 0 | O27: 0 | R27: 243000 | S27: =(B27+C27+D27+E27+F27+G27+H27+I27+J27+K27+M27+N27+O27+P27) -> 724500 | T27: =SUM(B27:R27) -> 967500
A28: 23rd | B28: 278500 | C28: 172000 | D28: 95000 | E28: 32500 | F28: 120000 | G28: 12000 | H28: 47000 | I28: 202000 | J28: 22000 | K28: 0 | O28: 6000 | R28: 1340000 | S28: =(B28+C28+D28+E28+F28+G28+H28+I28+J28+K28+M28+N28+O28+P28) -> 987000 | T28: =SUM(B28:R28) -> 2327000 | U28: BANKING
A29: 24th | B29: 318500 | C29: 136000 | D29: 123000 | E29: 57500 | F29: 188500 | H29: 57000 | I29: 65000 | J29: 12000 | K29: 0 | O29: 0 | R29: 0 | S29: =(B29+C29+D29+E29+F29+G29+H29+I29+J29+K29+M29+N29+O29+P29) -> 957500 | T29: =SUM(B29:R29) -> 957500 | U29: COFEE MACHINE FALTY
A30: 25th | B30: 392000 | C30: 410000 | D30: 150000 | E30: 41000 | F30: 162500 | H30: 157000 | I30: 110000 | J30: 30000 | K30: 0 | O30: 0 | R30: 0 | S30: =(B30+C30+D30+E30+F30+G30+H30+I30+J30+K30+M30+N30+O30+P30) -> 1452500 | T30: =SUM(B30:R30) -> 1452500
A31: 26th | B31: 264000 | C31: 259000 | D31: 201000 | E31: 16500 | F31: 205200 | H31: 139000 | I31: 157300 | J31: 16500 | K31: 0 | O31: 0 | R31: 17000 | S31: =(B31+C31+D31+E31+F31+G31+H31+I31+J31+K31+M31+N31+O31+P31) -> 1258500 | T31: =SUM(B31:R31) -> 1275500
A32: 27th | B32: 297500 | C32: 223000 | D32: 168000 | E32: 21000 | F32: 106700 | H32: 68000 | I32: 71000 | J32: 9000 | K32: 0 | O32: 0 | R32: 0 | S32: =(B32+C32+D32+E32+F32+G32+H32+I32+J32+K32+M32+N32+O32+P32) -> 964200 | T32: =SUM(B32:R32) -> 964200
A33: 28th | B33: 223500 | C33: 45000 | D33: 128000 | E33: 34500 | F33: 108000 | H33: 34000 | I33: 43000 | J33: 0 | K33: 0 | O33: 0 | R33: 26000 | S33: =(B33+C33+D33+E33+F33+G33+H33+I33+J33+K33+M33+N33+O33+P33) -> 616000 | T33: =SUM(B33:R33) -> 642000
A34: 29th | B34: 220500 | C34: 136000 | D34: 124500 | E34: 14000 | F34: 97000 | H34: 42000 | I34: 88500 | J34: 85500 | K34: 0 | O34: 0 | R34: 0 | S34: =(B34+C34+D34+E34+F34+G34+H34+I34+J34+K34+M34+N34+O34+P34) -> 808000 | T34: =SUM(B34:R34) -> 808000
A35: 30th | B35: 225500 | C35: 123000 | D35: 153500 | E35: 57000 | F35: 138500 | G35: 12000 | H35: 237000 | I35: 143500 | J35: 15000 | K35: 0 | O35: 0 | R35: 0 | S35: =(B35+C35+D35+E35+F35+G35+H35+I35+J35+K35+M35+N35+O35+P35) -> 1105000 | T35: =SUM(B35:R35) -> 1105000
A36: 31st | B36: 236000 | C36: 60000 | D36: 141000 | E36: 25000 | F36: 160500 | G36: 12000 | H36: 157000 | I36: 76500 | J36: 13000 | O36: 0 | R36: 0 | S36: =SUM(B36:R36) -> 881000 | T36: 711500
A37: GRAND TOTAL | B37: =SUM(B6:B36) -> 7683000 | C37: =SUM(C6:C36) -> 4305000 | D37: =SUM(D6:D36) -> 3749500 | E37: =SUM(E6:E36) -> 878000 | F37: =SUM(F6:F36) -> 4007800 | G37: =SUM(G6:G36) -> 174000 | H37: =SUM(H6:H36) -> 2507500 | I37: =SUM(I6:I36) -> 2198300 | ... T37: =SUM(T6:T36) -> 43136400

Sheet WEEKLY REPORT AUGUST 2023
B2: TotalEnergies MARKETING UGANDA LIMITED
B3: SHOP WEEKLY REPORT (MTD)
B6: SHOP NAME | C6: TotalEnergies RWIZI
B8: DATE: | C8: 01.08.2023
B9: Product category | C9: Week 1 | D9: week 2 | E9: Week 3 | F9: Week 4 | G9: Week 5 | H9: TOTAL
B10: Non Alcholic | C10: 1636000 | H10: =SUM(C10:G10) -> 1636000
B11: Alcoholic | C11: 888000 | H11: =SUM(C11:G11) -> 888000
B12: Fresh Products | C12: 898500 | H12: =SUM(C12:G12) -> 898500
B13: Ice creams | C13: 258000 | H13: =SUM(C13:G13) -> 258000
B14: Confectionery | C14: 797500 | H14: =SUM(C14:G14) -> 797500
B15: Tobacco | C15: 0 | H15: =SUM(C15:F15) -> 0
B16: Grocery | C16: 427000 | H16: =SUM(C16:G16) -> 427000
B17: Health & beauty | C17: 336000 | H17: =SUM(C17:G17) -> 336000
B18: Bazaar | C18: 63500 | H18: =SUM(C18:G18) -> 63500
B19: Car Care | H19: =SUM(C19:F19) -> 0
B20: Car wash | H20: =SUM(C20:F20) -> 0
B21: Press | H21: =SUM(C21:F21) -> 0
B22: Lottery | H22: =SUM(C22:F22) -> 0
B23: Coffee | C23: 54000 | H23: =SUM(C23:G23) -> 54000
B24: Snacks | H24: =SUM(C24:F24) -> 0
B25: Lubricants in shop | H25: =SUM(C25:F25) -> 0
B26: Guichet unique | H26: =SUM(C26:F26) -> 0
B27: Total | C27: =SUM(C10:C26) -> 5358500 | D27: =SUM(D10:D26) -> 0 | E27: =SUM(E10:E26) -> 0 | F27: =SUM(F10:F26) -> 0 | G27: =SUM(G10:G26) -> 0 | H27: =SUM(H10:H26) -> 5358500
B30: Maintenance Issues & Challenges

Sheet Daily sales for semp
B2: TotalEnergies MARKETING UGANDA LIMITED
B3: SHOP WEEKLY REPORT (MTD)
B4: SHOP NAME | C4: TotalEnergies RWIZI
B5: MONTH | C5: 45170
A6: DATE | B6: Non Alcholic | C6: Alcoholic | D6: Fresh products | E6: Ice cream | F6: Confectionery | G6: Tobacco | H6: Grocery | I6: Health & beauty | J6: Bazaar | K6: Car Care | L6: Car wash | M6: Press | N6: Lottery | O6: Coffee | P6: Snacks | Q6: Lubricants in shop | R6: Guichet | S6: Total T/O (Excluding Airtime, carwash,lubricants in shop) | T6: Global Total
A7: 1st | B7: 120000 | C7: 50000 | D7: 95000 | E7: 30000 | F7: 105000 | G7: 18000 | H7: 52000 | I7: 41000 | J7: 18000 | K7: 0 | O7: 0 | P7: 0 | Q7: 0 | T7: =SUM(B7:S7) -> 529000
A8: 2nd | B8: 278500 | C8: 210000 | D8: 154000 | E8: 26500 | F8: 251000 | G8: 24000 | H8: 182000 | I8: 147000 | J8: 18500 | K8: 0 | T8: =SUM(B8:S8) -> 1291500
A9: 3rd | B9: 189000 | C9: 72000 | D9: 78000 | E9: 25000 | F9: 83700 | G9: 0 | H9: 107000 | I9: 170000 | J9: 0 | K9: 0 | R9: -105000 | T9: =SUM(B9:S9) -> 619700
A10: 4th | B10: 232000 | C10: 77000 | D10: 107500 | E10: 14000 | F10: 122000 | G10: 0 | H10: 42000 | I10: 12500 | J10: 2000 | K10: 0 | R10: 31000 | T10: =SUM(B10:S10) -> 640000
A11: 5th | B11: 134000 | C11: 300000 | D11: 66000 | E11: 8500 | F11: 95000 | G11: 24000 | H11: 81000 | I11: 49500 | J11: 6000 | K11: 0 | R11: 940000 | T11: =SUM(B11:S11) -> 1704000
A12: 6th | B12: 139000 | C12: 157000 | D12: 104500 | E12: 12500 | F12: 134000 | G12: 24000 | H12: 18000 | I12: 20000 | J12: 2000 | K12: 0 | R12: 2437000 | T12: =SUM(B12:S12) -> 3048000
A13: 7th | B13: 147000 | C13: 85000 | D13: 57000 | E13: 9000 | F13: 87000 | G13: 6000 | H13: 50000 | I13: 60000 | J13: 10000 | K13: 0 | T13: =SUM(B13:S13) -> 511000
A14: 8th | B14: 244500 | C14: 78000 | D14: 150500 | E14: 70000 | F14: 132500 | G14: 6000 | H14: 81000 | I14: 60500 | J14: 9000 | K14: 0 | R14: 118000 | T14: =SUM(B14:S14) -> 950000
A15: 9th | B15: 262000 | C15: 207000 | D15: 130000 | E15: 36000 | F15: 152000 | G15: 0 | H15: 80000 | I15: 53000 | J15: 21000 | K15: 0 | R15: -66000 | T15: =SUM(B15:S15) -> 875000
A16: 10th | B16: 200000 | C16: 250000 | D16: 120000 | E16: 41500 | F16: 163500 | G16: 12000 | H16: 105000 | I16: 43500 | J16: 7000 | K16: 0 | R16: 252000 | T16: =SUM(B16:S16) -> 1194500
A17: 11th | B17: 114000 | C17: 300000 | D17: 91000 | E17: 0 | F17: 94000 | G17: 0 | H17: 15000 | I17: 87000 | J17: 0 | K17: 0 | T17: =SUM(B17:S17) -> 701000
A18: 12th | B18: 158500 | C18: 88000 | D18: 81000 | E18: 8500 | F18: 91500 | G18: 0 | H18: 71000 | I18: 15500 | J18: 0 | K18: 0 | R18: -69000 | T18: =SUM(B18:S18) -> 445000 | U18: BANKING
A19: 13th | B19: 176500 | C19: 116000 | D19: 91500 | E19: 24500 | F19: 120500 | G19: 6000 | H19: 44000 | I19: 69500 | J19: 0 | K19: 0 | R19: -3000 | T19: =SUM(B19:S19) -> 645500 | U19: BANKING
A20: 14th | B20: 206000 | C20: 69000 | D20: 93000 | E20: 23000 | F20: 100500 | G20: 12000 | H20: 103000 | I20: 19500 | J20: 11500 | K20: 0 | R20: 7000 | T20: =SUM(B20:S20) -> 644500
A21: 15th | B21: 205500 | C21: 230000 | D21: 78000 | E21: 12500 | F21: 174700 | G21: 6000 | H21: 36000 | I21: 62000 | J21: 20000 | K21: 0 | R21: -9000 | T21: =SUM(B21:S21) -> 815700
A22: 16TH | B22: 258000 | C22: 306000 | D22: 126000 | E22: 17000 | F22: 167500 | G22: 0 | H22: 74500 | I22: 79000 | J22: 5000 | K22: 0 | R22: -201000 | T22: =SUM(B22:S22) -> 832000
A23: 17th | B23: 201000 | C23: 264000 | D23: 133000 | E23: 15000 | F23: 122900 | G23: 12000 | H23: 114000 | I23: 56000 | J23: 5000 | K23: 0 | R23: 200000 | T23: =SUM(B23:S23) -> 1122900 | U23: BANKING
A24: 18th | B24: 192000 | C24: 50000 | D24: 88500 | E24: 7000 | F24: 143000 | G24: 12000 | H24: 124000 | I24: 73000 | J24: 0 | K24: 0 | R24: -5000 | T24: =SUM(B24:S24) -> 684500
A25: 19th | B25: 194000 | C25: 26000 | D25: 37500 | E25: 8000 | F25: 51000 | G25: 0 | H25: 111000 | I25: 87000 | J25: 4000 | K25: 0 | T25: =SUM(B25:S25) -> 518500
A26: 20th | B26: 170000 | C26: 63000 | D26: 73000 | E26: 23500 | F26: 98500 | G26: 0 | H26: 210000 | I26: 35000 | J26: 0 | K26: 0 | T26: =SUM(B26:S26) -> 673000
A27: 21st | B27: 231000 | C27: 83000 | D27: 123000 | E27: 15500 | F27: 156000 | G27: 6000 | H27: 106000 | I27: 80000 | J27: 0 | K27: 0 | T27: =SUM(B27:S27) -> 800500
A28: 22nd | B28: 214000 | C28: 120000 | D28: 77000 | E28: 2500 | F28: 98000 | G28: 0 | H28: 36500 | I28: 66000 | J28: 0 | K28: 0 | T28: =SUM(B28:S28) -> 614000
A29: 23rd | B29: 208000 | C29: 90000 | D29: 85500 | E29: 21500 | F29: 167500 | G29: 0 | H29: 66000 | I29: 32500 | J29: 0 | K29: 0 | T29: =SUM(B29:S29) -> 671000 | U29: BANKING
A30: 24th | B30: 247500 | C30: 41000 | D30: 104500 | E30: 15500 | F30: 117500 | G30: 0 | H30: 67000 | I30: 33000 | J30: 2000 | K30: 0 | T30: =SUM(B30:S30) -> 628000 | U30: COFEE MACHINE FALTY
A31: 25th | B31: 183000 | C31: 68000 | D31: 117500 | E31: 11000 | F31: 116700 | G31: 0 | H31: 44000 | I31: 29000 | J31: 0 | K31: 0 | T31: =SUM(B31:S31) -> 569200
A32: 26th | B32: 120000 | C32: 41000 | D32: 57000 | E32: 4500 | F32: 116000 | G32: 0 | H32: 99500 | I32: 37000 | J32: 0 | K32: 0 | T32: =SUM(B32:S32) -> 475000
A33: 27th | B33: 155000 | C33: 139000 | D33: 49000 | E33: 12000 | F33: 100000 | G33: 0 | H33: 98000 | I33: 42000 | J33: 38000 | K33: 0 | T33: =SUM(B33:S33) -> 633000
A34: 28th | B34: 217000 | C34: 57000 | D34: 109000 | E34: 5000 | F34: 146000 | G34: 0 | H34: 39000 | I34: 20000 | J34: 0 | K34: 0 | T34: =SUM(B34:S34) -> 593000
A35: 29th | B35: 170000 | C35: 185000 | D35: 97000 | E35: 10500 | F35: 164000 | G35: 6000 | H35: 90500 | I35: 76000 | J35: 2000 | K35: 0 | T35: =SUM(B35:S35) -> 801000
A36: 30th | B36: 190500 | C36: 60000 | D36: 96500 | E36: 38500 | F36: 144000 | G36: 0 | H36: 27000 | I36: 52000 | J36: 2000 | K36: 0 | T36: =SUM(B36:S36) -> 610500
A37: 31st
A38: GRAND TOTAL | B38: =SUM(B7:B37) -> 5757500 | C38: =SUM(C7:C37) -> 3882000 | D38: =SUM(D7:D37) -> 2871000 | E38: =SUM(E7:E37) -> 548500 | F38: =SUM(F7:F37) -> 3815500 | G38: =SUM(G7:G37) -> 174000 | H38: =SUM(H7:H37) -> 2374000 | I38: =SUM(I7:I37) -> 1708000 | ... T38: =SUM(T7:T37) -> 24840500

Sheet WEEKLY REPORT SEP 2023
B3: TotalEnergies MARKETING UGANDA LIMITED
B4: SHOP WEEKLY REPORT (MTD)
B7: SHOP NAME | C7: TotalEnergies RWIZI
B9: DATE: | C9: 01.08.2023
B10: Product category | C10: Week 1 | D10: week 2 | E10: Week 3 | F10: Week 4 | G10: Week 5 | H10: TOTAL
B11: Non Alcholic | C11: 587500 | D11: 1358500 | E11: 1118500 | F11: 1657500 | G11: 1035500 | H11: =SUM(C11:G11) -> 5757500
B12: Alcoholic | C12: 332000 | D12: 1154000 | E12: 1373000 | F12: 473000 | G12: 550000 | H12: =SUM(C12:G12) -> 3882000
B13: Fresh Products | C13: 327000 | D13: 735500 | E13: 693500 | F13: 589000 | G13: 526000 | H13: =SUM(C13:G13) -> 2871000
B14: Ice creams | C14: 81500 | D14: 191500 | E14: 100500 | F14: 93500 | G14: 81500 | H14: =SUM(C14:G14) -> 548500
B15: Confectionery | C15: 439700 | D15: 886000 | E15: 871600 | F15: 831500 | G15: 786700 | H15: =SUM(C15:G15) -> 3815500
B16: Tobacco | C16: 42000 | D16: 72000 | E16: 36000 | F16: 18000 | G16: 6000 | H16: =SUM(C16:G16) -> 174000
B17: Grocery | C17: 341000 | D17: 457000 | E17: 457500 | F17: 720500 | G17: 398000 | H17: =SUM(C17:G17) -> 2374000
B18: Health & beauty | C18: 358000 | D18: 299000 | E18: 388500 | F18: 406500 | G18: 256000 | H18: =SUM(C18:G18) -> 1708000
B19: Bazaar | C19: 36500 | D19: 57000 | E19: 41500 | F19: 6000 | G19: 42000 | H19: =SUM(C19:G19) -> 183000
B20: Car Care | H20: =SUM(C20:F20) -> 0
B21: Car wash | H21: =SUM(C21:F21) -> 0
B22: Press | H22: =SUM(C22:F22) -> 0
B23: Lottery | H23: =SUM(C23:F23) -> 0
B24: Coffee | C24: 42000 | D24: 37000 | E24: 84000 | F24: 47000 | G24: 0 | H24: =SUM(C24:G24) -> 210000
B25: Snacks | H25: =SUM(C25:F25) -> 0
B26: Lubricants in shop | H26: =SUM(C26:F26) -> 0
B27: Guichet unique | H27: =SUM(C27:F27) -> 0
B28: Total | C28: =SUM(C11:C27) -> 2587200 | D28: =SUM(D11:D27) -> 5247500 | E28: =SUM(E11:E27) -> 5164600 | F28: =SUM(F11:F27) -> 4842500 | G28: =SUM(G11:G27) -> 3681700 | H28: =SUM(H11:H27) -> 21523500
B31: Maintenance Issues & Challenges

Sheet DAILY SALES OCT 2023
B2: TotalEnergies MARKETING UGANDA LIMITED
B3: SHOP WEEKLY REPORT (MTD)
B4: SHOP NAME | C4: TotalEnergies RWIZI
B5: MONTH | C5: 45200
A6: DATE | B6: Non Alcholic | C6: Alcoholic | D6: Fresh products | E6: Ice cream | F6: Confectionery | G6: Tobacco | H6: Grocery | I6: Health & beauty | J6: Bazaar | K6: Car Care | L6: Car wash | M6: Press | N6: Lottery | O6: Coffee | P6: Snacks | Q6: Lubricants in shop | R6: Guichet | S6: Total T/O (Excluding Airtime, carwash,lubricants in shop) | T6: Global Total
A7: 1st | B7: 104000 | C7: 22000 | D7: 81500 | E7: 12000 | F7: 74500 | H7: 18000 | I7: 0 | J7: 8000 | K7: 0 | O7: 4000 | P7: 0 | Q7: 0 | T7: =SUM(B7:S7) -> 324000
A8: 2nd | B8: 174000 | C8: 47000 | D8: 103000 | E8: 11000 | F8: 149000 | G8: 24000 | H8: 100000 | I8: 60000 | J8: 2000 | K8: 0 | O8: 12000 | T8: =SUM(B8:S8) -> 682000
A9: 3rd | B9: 150000 | C9: 24000 | D9: 107000 | E9: 18000 | F9: 106000 | H9: 53000 | I9: 27500 | J9: 12000 | K9: 0 | O9: 4000 | T9: =SUM(B9:S9) -> 501500
A10: 4th | B10: 150000 | C10: 66000 | D10: 160000 | E10: 22000 | F10: 100000 | H10: 36000 | I10: 29000 | J10: 2000 | K10: 0 | O10: 0 | T10: =SUM(B10:S10) -> 565000
A11: 5th | B11: 166000 | C11: 46000 | D11: 76000 | E11: 24000 | F11: 107000 | G11: 12000 | H11: 37000 | I11: 40500 | J11: 2000 | K11: 0 | O11: 20000 | T11: =SUM(B11:S11) -> 530500
A12: 6th | B12: 305000 | C12: 366000 | D12: 125000 | E12: 22000 | F12: 108000 | H12: 43000 | I12: 63000 | J12: 8000 | K12: 0 | O12: 12000 | T12: =SUM(B12:S12) -> 1052000
A13: 7th | B13: 176000 | C13: 500000 | D13: 88000 | E13: 15000 | F13: 131500 | H13: 170000 | I13: 158500 | J13: 15000 | K13: 0 | O13: 0 | T13: =SUM(B13:S13) -> 1254000
A14: 8th | B14: 210000 | C14: 120000 | D14: 75000 | E14: 8000 | F14: 122000 | H14: 27500 | I14: 12000 | J14: 6000 | K14: 0 | O14: 0 | T14: =SUM(B14:S14) -> 580500
A15: 9th | B15: 152000 | C15: 51000 | D15: 124000 | E15: 20000 | F15: 214000 | H15: 54000 | I15: 28500 | J15: 8500 | K15: 0 | O15: 0 | T15: =SUM(B15:S15) -> 652000
A16: 10th | B16: 172000 | C16: 132000 | D16: 67000 | E16: 15500 | F16: 133000 | G16: 6000 | H16: 63000 | I16: 82000 | K16: 0 | O16: 0 | T16: =SUM(B16:S16) -> 670500
A17: 11th | B17: 87500 | C17: 38000 | D17: 72000 | E17: 0 | F17: 97500 | G17: 6000 | H17: 86000 | I17: 54000 | J17: 1000 | K17: 0 | O17: 16000 | T17: =SUM(B17:S17) -> 458000
A18: 12th | B18: 178500 | C18: 81000 | D18: 116500 | E18: 5000 | F18: 123000 | G18: 36000 | H18: 19000 | I18: 22000 | K18: 0 | O18: 8000 | T18: =SUM(B18:S18) -> 589000
A19: 13th | B19: 183000 | C19: 121000 | D19: 88500 | E19: 15500 | F19: 123500 | H19: 6000 | I19: 20000 | J19: 8000 | K19: 0 | O19: 0 | T19: =SUM(B19:S19) -> 565500
A20: 14th | B20: 206000 | C20: 211000 | D20: 154000 | E20: 7500 | F20: 139000 | H20: 86500 | I20: 90000 | J20: 17000 | K20: 0 | O20: 8000 | T20: =SUM(B20:S20) -> 919000
A21: 15th | B21: 167500 | C21: 83000 | D21: 79000 | E21: 19000 | F21: 118000 | H21: 34500 | I21: 25000 | J21: 13000 | K21: 0 | O21: 0 | T21: =SUM(B21:S21) -> 539000
A22: 16TH | B22: 165500 | C22: 24000 | D22: 93500 | E22: 4500 | F22: 89000 | H22: 38000 | I22: 38500 | J22: 2000 | K22: 0 | O22: 12000 | T22: =SUM(B22:S22) -> 467000
A23: 17th | B23: 232000 | C23: 25000 | D23: 77500 | E23: 6500 | F23: 109500 | H23: 33000 | I23: 63500 | J23: 5000 | K23: 0 | O23: 8000 | T23: =SUM(B23:S23) -> 560000
A24: 18th | B24: 147000 | C24: 40000 | D24: 82000 | E24: 12500 | F24: 103500 | H24: 56000 | I24: 101500 | J24: 2000 | K24: 0 | O24: 0 | T24: =SUM(B24:S24) -> 544500
A25: 19th | B25: 142000 | C25: 46000 | D25: 62000 | E25: 14500 | F25: 115500 | H25: 46000 | I25: 27000 | J25: 4000 | K25: 0 | O25: 9000 | T25: =SUM(B25:S25) -> 466000
A26: 20th | B26: 180000 | C26: 122000 | D26: 102000 | E26: 4000 | F26: 126000 | G26: 12000 | H26: 138000 | I26: 29000 | J26: 13000 | K26: 0 | O26: 0 | T26: =SUM(B26:S26) -> 726000
A27: 21st | B27: 173000 | C27: 102000 | D27: 100000 | E27: 21000 | F27: 95000 | H27: 55000 | I27: 31000 | J27: 4000 | K27: 0 | O27: 4000 | T27: =SUM(B27:S27) -> 585000
A28: 22nd | B28: 239500 | C28: 92000 | D28: 139000 | E28: 21500 | F28: 117000 | H28: 80000 | I28: 50500 | J28: 6000 | K28: 0 | O28: 10000 | T28: =SUM(B28:S28) -> 755500
A29: 23rd | B29: 117000 | C29: 69000 | D29: 98000 | E29: 24000 | F29: 66500 | H29: 95000 | I29: 94500 | J29: 9000 | K29: 0 | O29: 4000 | T29: =SUM(B29:S29) -> 577000
A30: 24th | B30: 144500 | C30: 51000 | D30: 81500 | E30: 8000 | F30: 90000 | H30: 18000 | I30: 44000 | J30: 4000 | K30: 0 | O30: 8000 | T30: =SUM(B30:S30) -> 449000
A31: 25th | B31: 112000 | C31: 84000 | D31: 74000 | E31: 25000 | F31: 35000 | G31: 12000 | H31: 45000 | I31: 21000 | J31: 21000 | K31: 0 | O31: 0 | T31: =SUM(B31:S31) -> 429000
A32: 26th | B32: 104500 | C32: 87000 | D32: 126000 | E32: 7000 | F32: 113500 | H32: 37000 | I32: 31500 | J32: 3000 | K32: 0 | O32: 21000 | T32: =SUM(B32:S32) -> 530500
A33: 27th | B33: 215500 | C33: 98000 | D33: 85000 | E33: 5500 | F33: 221000 | H33: 46000 | I33: 25000 | J33: 30600 | K33: 0 | O33: 1000 | T33: =SUM(B33:S33) -> 727600
A34: 28th | B34: 217500 | C34: 200000 | D34: 165000 | E34: 36500 | F34: 188900 | G34: 12000 | H34: 127500 | I34: 44000 | J34: 9000 | K34: 0 | O34: 21000 | T34: =SUM(B34:S34) -> 1021400
A35: 29th | B35: 244500 | C35: 200000 | D35: 173500 | E35: 26000 | F35: 242500 | G35: 0 | H35: 217500 | I35: 16500 | J35: 8000 | O35: 0 | T35: =SUM(B35:S35) -> 1128500
A36: 30th | B36: 190500 | C36: 68000 | D36: 118500 | E36: 5500 | F36: 132500 | G36: 0 | H36: 71000 | I36: 71000 | J36: 5000 | K36: 0 | O36: 18000 | T36: =SUM(B36:S36) -> 680000
A37: 31st | B37: 165500 | C37: 61000 | D37: 76000 | E37: 0 | F37: 102500 | G37: 0 | H37: 35000 | I37: 37500 | J37: 16000 | O37: 23000 | T37: =SUM(B37:S37) -> 516500
A38: GRAND TOTAL | B38: =SUM(B7:B37) -> 5372000 | C38: =SUM(C7:C37) -> 3277000 | D38: =SUM(D7:D37) -> 3170000 | E38: =SUM(E7:E37) -> 436500 | F38: =SUM(F7:F37) -> 3793900 | G38: =SUM(G7:G37) -> 120000 | H38: =SUM(H7:H37) -> 1971500 | I38: =SUM(I7:I37) -> 1438000 | ... T38: =SUM(T7:T37) -> 20046000

Sheet WEEKLY REPORT OCT  2023 
B3: TotalEnergies MARKETING UGANDA LIMITED
B4: SHOP WEEKLY REPORT (MTD)
B7: SHOP NAME | C7: TotalEnergies RWIZI
B9: DATE: | C9: 01.10.2023
B10: Product category | C10: Week 1 | D10: week 2 | E10: Week 3 | F10: Week 4 | G10: Week 5 | H10: TOTAL
B11: Non Alcholic | C11: 1435000 | D11: 1146500 | E11: 1279000 | F11: 1155500 | G11: 356000 | H11: =SUM(C11:G11) -> 5372000
B12: Alcoholic | C12: 1191000 | D12: 717000 | E12: 451000 | F12: 789000 | G12: 129000 | H12: =SUM(C12:G12) -> 3277000
B13: Fresh Products | C13: 815500 | D13: 701000 | E13: 656000 | F13: 803000 | G13: 194500 | H13: =SUM(C13:G13) -> 3170000
B14: Ice creams | C14: 132000 | D14: 82500 | E14: 84500 | F14: 132000 | G14: 5500 | H14: =SUM(C14:G14) -> 436500
B15: Confectionery | C15: 898000 | D15: 948000 | E15: 755500 | F15: 957400 | G15: 235000 | H15: =SUM(C15:G15) -> 3793900
B16: Tobacco | C16: 36000 | D16: 48000 | E16: 12000 | F16: 24000 | H16: =SUM(C16:G16) -> 120000
B17: Grocery | C17: 484500 | D17: 349000 | E17: 446000 | F17: 586000 | G17: 106000 | H17: =SUM(C17:G17) -> 1971500
B18: Health & beauty | C18: 390500 | D18: 321500 | E18: 341000 | F18: 276500 | G18: 108500 | H18: =SUM(C18:G18) -> 1438000
B19: Bazaar | C19: 55000 | D19: 47500 | E19: 36000 | F19: 84600 | G19: 21000 | H19: =SUM(C19:G19) -> 244100
B20: Car Care | H20: =SUM(C20:F20) -> 0
B21: Car wash | H21: =SUM(C21:F21) -> 0
B22: Press | H22: =SUM(C22:F22) -> 0
B23: Lottery | H23: =SUM(C23:F23) -> 0
B24: Coffee | C24: 52000 | D24: 32000 | E24: 43000 | F24: 51000 | G24: 45000 | H24: =SUM(C24:G24) -> 223000
B25: Snacks | H25: =SUM(C25:F25) -> 0
B26: Lubricants in shop | H26: =SUM(C26:F26) -> 0
B27: Guichet unique | H27: =SUM(C27:F27) -> 0
B28: Total | C28: =SUM(C11:C27) -> 5489500 | D28: =SUM(D11:D27) -> 4393000 | E28: =SUM(E11:E27) -> 4104000 | F28: =SUM(F11:F27) -> 4859000 | G28: =SUM(G11:G27) -> 1200500 | H28: =SUM(H11:H27) -> 20046000
B31: Maintenance Issues & Challenges
B32: DUE TO DAILY HEAVY RAINS THIS HAS AFFECTED SALES BY DROPPING DOWN.

Sheet DAILY SALES NOV 2023
B2: TotalEnergies MARKETING UGANDA LIMITED
B3: SHOP WEEKLY REPORT (MTD)
B4: SHOP NAME | C4: TotalEnergies RWIZI
B5: MONTH | C5: 45231
A6: DATE | B6: Non Alcholic | C6: Alcoholic | D6: Fresh products | E6: Ice cream | F6: Confectionery | G6: Tobacco | H6: Grocery | I6: Health & beauty | J6: Bazaar | K6: Car Care | L6: Car wash | M6: Press | N6: Lottery | O6: Coffee | P6: Snacks | Q6: Lubricants in shop | R6: Guichet | S6: Total T/O (Excluding Airtime, carwash,lubricants in shop) | T6: Global Total
A7: 1st | B7: 215500 | C7: 117000 | D7: 81500 | E7: 3000 | F7: 66000 | G7: 6000 | H7: 24000 | I7: 35500 | J7: 11000 | K7: 0 | O7: 0 | P7: 0 | Q7: 0 | R7: -120000 | T7: =SUM(B7:S7) -> 439500
A8: 2nd | B8: 113000 | C8: 114000 | D8: 74000 | E8: 5500 | F8: 100500 | G8: 0 | H8: 40000 | I8: 11500 | J8: 9500 | K8: 0 | O8: 1000 | R8: 1170000 | T8: =SUM(B8:S8) -> 1639000
A9: 3rd | B9: 154000 | C9: 280000 | D9: 28000 | E9: 0 | F9: 78000 | G9: 0 | H9: 17500 | I9: 11000 | J9: 16000 | K9: 0 | O9: 22000 | R9: 0 | T9: =SUM(B9:S9) -> 606500
A10: 4th | B10: 178000 | C10: 119000 | D10: 116500 | E10: 13000 | F10: 185000 | G10: 0 | H10: 61000 | I10: 65500 | J10: 10000 | K10: 0 | O10: 28000 | R10: -68000 | T10: =SUM(B10:S10) -> 708000
A11: 5th | B11: 185500 | C11: 341000 | D11: 73500 | E11: 21000 | F11: 200500 | G11: 0 | H11: 105000 | I11: 49000 | J11: 7000 | K11: 0 | O11: 7000 | T11: =SUM(B11:S11) -> 989500
A12: 6th | B12: 215000 | C12: 107000 | D12: 79000 | E12: 0 | F12: 19000 | G12: 0 | H12: 18000 | I12: 26000 | J12: 2000 | K12: 0 | O12: 26000 | R12: -744000 | T12: =SUM(B12:S12) -> -252000
A13: 7th | B13: 133500 | C13: 67000 | D13: 53500 | E13: 3000 | F13: 70000 | G13: 12000 | H13: 18000 | I13: 20000 | J13: 4000 | K13: 0 | O13: 5000 | T13: =SUM(B13:S13) -> 386000 | U13: 500000
A14: 8th | B14: 206000 | C14: 149000 | D14: 77000 | E14: 2000 | F14: 82900 | G14: 0 | H14: 28500 | I14: 4500 | J14: 5400 | K14: 0 | O14: 16000 | T14: =SUM(B14:S14) -> 571300
A15: 9th | B15: 234500 | C15: 56000 | D15: 77000 | E15: 20000 | F15: 126500 | G15: 12000 | H15: 54000 | I15: 19000 | J15: 4000 | K15: 0 | O15: 11000 | T15: =SUM(B15:S15) -> 614000
A16: 10th | B16: 191500 | C16: 16000 | D16: 101500 | E16: 18500 | F16: 147500 | G16: 0 | H16: 61800 | I16: 30500 | J16: 8000 | K16: 0 | O16: 18000 | R16: 516000 | T16: =SUM(B16:S16) -> 1109300
A17: 11th | B17: 152500 | C17: 51000 | D17: 106000 | E17: 7000 | F17: 107000 | G17: 0 | H17: 61000 | I17: 55500 | J17: 5000 | K17: 0 | O17: 40000 | R17: 438000 | T17: =SUM(B17:S17) -> 1023000
A18: 12th | B18: 135000 | C18: 60000 | D18: 108500 | E18: 38000 | F18: 131500 | G18: 6000 | H18: 128000 | I18: 54000 | J18: 6000 | K18: 0 | O18: 16000 | R18: 28000 | T18: =SUM(B18:S18) -> 711000
A19: 13th | B19: 123000 | C19: 17000 | D19: 56000 | E19: 16500 | F19: 73000 | G19: 0 | H19: 10000 | I19: 50500 | J19: 11000 | K19: 0 | O19: 18000 | R19: 2000 | T19: =SUM(B19:S19) -> 377000
A20: 14th | B20: 108000 | C20: 106000 | D20: 57000 | E20: 1500 | F20: 51000 | G20: 0 | H20: 12000 | I20: 48300 | J20: 0 | K20: 0 | O20: 10000 | R20: 1020000 | T20: =SUM(B20:S20) -> 1413800
A21: 15th | B21: 137000 | C21: 39000 | D21: 74000 | E21: 4000 | F21: 143000 | G21: 0 | H21: 36000 | I21: 41000 | J21: 10000 | K21: 0 | O21: 20000 | R21: 89000 | T21: =SUM(B21:S21) -> 593000
A22: 16TH | B22: 203000 | C22: 120000 | D22: 130000 | E22: 12000 | F22: 54000 | G22: 0 | H22: 42400 | I22: 10000 | J22: 30000 | K22: 0 | O22: 18000 | R22: 117000 | T22: =SUM(B22:S22) -> 736400
A23: 17th | B23: 229000 | C23: 276000 | D23: 104000 | E23: 4000 | F23: 102000 | G23: 0 | H23: 54000 | I23: 20000 | J23: 7000 | K23: 0 | O23: 64000 | R23: -48000 | T23: =SUM(B23:S23) -> 812000
A24: 18th | B24: 156500 | C24: 285000 | D24: 86000 | E24: 0 | F24: 110500 | G24: 0 | H24: 61000 | I24: 20300 | J24: 6700 | K24: 0 | O24: 18000 | R24: 435000 | T24: =SUM(B24:S24) -> 1179000 | U24: 1900000
A25: 19th | B25: 141500 | C25: 104000 | D25: 61500 | E25: 20500 | F25: 113800 | G25: 0 | H25: 56000 | I25: 33500 | J25: 7000 | K25: 0 | O25: 6000 | R25: 2000 | T25: =SUM(B25:S25) -> 545800 | U25: 435000
A26: 20th | B26: 116000 | C26: 96000 | D26: 86000 | E26: 5500 | F26: 69500 | G26: 0 | H26: 16000 | I26: 33000 | J26: 0 | K26: 0 | O26: 6000 | R26: 11000 | T26: =SUM(B26:S26) -> 439000
A27: 21st | B27: 112000 | C27: 155000 | D27: 64000 | E27: 5000 | F27: 77000 | G27: 60000 | H27: 43000 | I27: 26000 | J27: 4000 | K27: 0 | O27: 24000 | R27: 63000 | T27: =SUM(B27:S27) -> 633000
A28: 22nd | B28: 99500 | C28: 156000 | D28: 89000 | E28: 7500 | F28: 56000 | G28: 0 | H28: 22000 | I28: 70000 | J28: 0 | K28: 0 | O28: 10000 | R28: 63000 | T28: =SUM(B28:S28) -> 573000
A29: 23rd | B29: 99500 | C29: 90000 | D29: 54000 | E29: 1500 | F29: 68800 | G29: 0 | H29: 18000 | I29: 16500 | J29: 0 | K29: 0 | O29: 24000 | T29: =SUM(B29:S29) -> 372300
A30: 24th | B30: 254000 | C30: 112000 | D30: 100000 | E30: 25000 | F30: 164000 | G30: 0 | H30: 28000 | I30: 40000 | J30: 12000 | K30: 0 | O30: 18000 | R30: 836000 | T30: =SUM(B30:S30) -> 1589000
A31: 25th | B31: 242000 | C31: 194000 | D31: 113000 | E31: 17100 | F31: 126000 | G31: 0 | H31: 68000 | I31: 19000 | J31: 9000 | K31: 0 | O31: 48000 | R31: 792000 | T31: =SUM(B31:S31) -> 1628100 | U31: 1710000
A32: 26th | B32: 107500 | C32: 122000 | D32: 83300 | E32: 9000 | F32: 95500 | G32: 66000 | H32: 31000 | I32: 20000 | J32: 6000 | K32: 0 | O32: 22000 | R32: 115000 | T32: =SUM(B32:S32) -> 677300
A33: 27th | B33: 172500 | C33: 72000 | D33: 78500 | E33: 6000 | F33: 95600 | G33: 0 | H33: 12000 | I33: 2000 | J33: 3400 | K33: 0 | O33: 30000 | R33: 1050500 | T33: =SUM(B33:S33) -> 1522500 | U33: 1150000
A34: 28th | B34: 143500 | C34: 106000 | D34: 12000 | E34: 20000 | F34: 205000 | G34: 0 | H34: 68000 | I34: 1000 | J34: 14000 | K34: 0 | O34: 11000 | T34: =SUM(B34:S34) -> 580500 | U34: 107000
A35: 29th | B35: 225000 | C35: 91000 | D35: 77000 | E35: 6000 | F35: 113000 | G35: 12000 | H35: 31000 | I35: 51000 | J35: 0 | O35: 14000 | R35: 42000 | T35: =SUM(B35:S35) -> 662000
A36: 30th | B36: 76500 | C36: 62000 | D36: 74500 | E36: 13000 | F36: 82500 | G36: 0 | H36: 159500 | I36: 20000 | J36: 10000 | K36: 0 | O36: 6000 | R36: 2000 | T36: =SUM(B36:S36) -> 506000
A37: 31st | T37: =SUM(B37:S37) -> 0
A38: GRAND TOTAL | B38: =SUM(B7:B37) -> 4860000 | C38: =SUM(C7:C37) -> 3680000 | D38: =SUM(D7:D37) -> 2375800 | E38: =SUM(E7:E37) -> 305100 | F38: =SUM(F7:F37) -> 3114600 | G38: =SUM(G7:G37) -> 174000 | H38: =SUM(H7:H37) -> 1384700 | I38: =SUM(I7:I37) -> 904100 | ... T38: =SUM(T7:T37) -> 23384800

Sheet WEEKLY REPORT NOV  2023  (2)
B3: TotalEnergies MARKETING UGANDA LIMITED
B4: SHOP WEEKLY REPORT (MTD)
B7: SHOP NAME | C7: TotalEnergies RWIZI
B9: DATE: | C9: 01.11.2023
B10: Product category | C10: Week 1 | D10: week 2 | E10: Week 3 | F10: Week 4 | G10: Week 5 | H10: TOTAL
B11: Non Alcholic | C11: 846000 | D11: 1268000 | E11: 1098000 | F11: 1030500 | G11: 617500 | H11: =SUM(C11:G11) -> 4860000
B12: Alcoholic | C12: 971000 | D12: 506000 | E12: 947000 | F12: 925000 | G12: 331000 | H12: =SUM(C12:G12) -> 3680000
B13: Fresh Products | C13: 373500 | D13: 602500 | E13: 568500 | F13: 589300 | G13: 242000 | H13: =SUM(C13:G13) -> 2375800
B14: Ice creams | C14: 42500 | D14: 88500 | E14: 58500 | F14: 70600 | G14: 45000 | H14: =SUM(C14:G14) -> 305100
B15: Confectionery | C15: 630000 | D15: 684400 | E15: 647300 | F15: 656800 | G15: 496100 | H15: =SUM(C15:G15) -> 3114600
B16: Tobacco | C16: 6000 | D16: 30000 | E16: 0 | F16: 126000 | G16: 12000 | H16: =SUM(C16:G16) -> 174000
B17: Grocery | C17: 247500 | D17: 369300 | E17: 271000 | F17: 226000 | G17: 270500 | H17: =SUM(C17:G17) -> 1384300
B18: Health & beauty | C18: 172500 | D18: 209500 | E18: 223600 | F18: 224500 | G18: 74000 | H18: =SUM(C18:G18) -> 904100
B19: Bazaar | C19: 53500 | D19: 34400 | E19: 71700 | F19: 31000 | G19: 27400 | H19: =SUM(C19:G19) -> 218000
B20: Car Care | H20: =SUM(C20:F20) -> 0
B21: Car wash | H21: =SUM(C21:F21) -> 0
B22: Press | H22: =SUM(C22:F22) -> 0
B23: Lottery | H23: =SUM(C23:F23) -> 0
B24: Coffee | C24: 58000 | D24: 132000 | E24: 154000 | F24: 152000 | G24: 61000 | H24: =SUM(C24:G24) -> 557000
B25: Snacks | H25: =SUM(C25:F25) -> 0
B26: Lubricants in shop | H26: =SUM(C26:F26) -> 0
B27: Guichet unique | H27: =SUM(C27:F27) -> 0
B28: Total | C28: =SUM(C11:C27) -> 3400500 | D28: =SUM(D11:D27) -> 3924600 | E28: =SUM(E11:E27) -> 4039600 | F28: =SUM(F11:F27) -> 4031700 | G28: =SUM(G11:G27) -> 2176500 | H28: =SUM(H11:H27) -> 17572900
B31: Maintenance Issues & Challenges
B32: DUE TO DAILY HEAVY RAINS THIS HAS AFFECTED SALES BY DROPPING DOWN.

Sheet DAILY SALES DEC 2023 
B2: TotalEnergies MARKETING UGANDA LIMITED
B3: SHOP WEEKLY REPORT (MTD)
B4: SHOP NAME | C4: TotalEnergies RWIZI
B5: MONTH | C5: 45261
A6: DATE | B6: Non Alcholic | C6: Alcoholic | D6: Fresh products | E6: Ice cream | F6: Confectionery | G6: Tobacco | H6: Grocery | I6: Health & beauty | J6: Bazaar | K6: Car Care | L6: Car wash | M6: Press | N6: Lottery | O6: Coffee | P6: Snacks | Q6: Lubricants in shop | R6: Guichet | S6: Total T/O (Excluding Airtime, carwash,lubricants in shop) | T6: Global Total
A7: 1st | B7: 310000 | C7: 105000 | D7: 170000 | E7: 10500 | F7: 114500 | G7: 24000 | H7: 35500 | I7: 76000 | J7: 4000 | K7: 0 | O7: 16000 | P7: 0 | Q7: 0 | T7: =SUM(B7:S7) -> 865500
A8: 2nd | B8: 224000 | C8: 268000 | D8: 130500 | E8: 0 | F8: 107500 | H8: 55000 | I8: 19500 | J8: 35000 | K8: 0 | O8: 12000 | T8: =SUM(B8:S8) -> 851500
A9: 3rd | B9: 164000 | C9: 64000 | D9: 80000 | E9: 38000 | F9: 124000 | H9: 57000 | I9: 37000 | K9: 0 | O9: 4000 | T9: =SUM(B9:S9) -> 568000
A10: 4th | B10: 205000 | C10: 43000 | D10: 76500 | E10: 13000 | F10: 144300 | H10: 103000 | I10: 87000 | J10: 12000 | K10: 0 | O10: 27000 | R10: 1203000 | T10: =SUM(B10:S10) -> 1913800
A11: 5th | B11: 139000 | C11: 62000 | D11: 92000 | E11: 18500 | F11: 105500 | H11: 48000 | I11: 14000 | J11: 5000 | K11: 0 | O11: 16000 | R11: 1904000 | T11: =SUM(B11:S11) -> 2404000 | U11: 1610000
A12: 6th | B12: 152000 | C12: 63000 | D12: 46000 | E12: 2000 | F12: 83000 | H12: 38000 | I12: 4000 | K12: 0 | O12: 6000 | R12: -218000 | T12: =SUM(B12:S12) -> 176000
A13: 7th | B13: 249000 | C13: 155000 | D13: 131500 | E13: 13000 | F13: 81000 | H13: 24000 | I13: 113500 | K13: 0 | O13: 4000 | R13: 745000 | T13: =SUM(B13:S13) -> 1516000 | U13: 1500000
A14: 8th | B14: 181500 | C14: 172000 | D14: 160000 | E14: 18000 | F14: 143000 | H14: 53000 | I14: 67000 | J14: 25000 | K14: 0 | R14: 188000 | T14: =SUM(B14:S14) -> 1007500
A15: 9th | B15: 224500 | C15: 110000 | D15: 117000 | E15: 4000 | F15: 137500 | G15: 24000 | H15: 99000 | I15: 99000 | J15: 20000 | K15: 0 | O15: 8000 | R15: 930000 | T15: =SUM(B15:S15) -> 1773000
A16: 10th | B16: 172000 | C16: 66000 | D16: 75500 | E16: 27000 | F16: 134000 | H16: 22000 | I16: 18500 | K16: 0 | O16: 8000 | R16: 477000 | T16: =SUM(B16:S16) -> 1000000 | U16: 1800000
A17: 11th | B17: 289000 | C17: 100000 | D17: 108500 | E17: 9000 | F17: 112000 | H17: 34000 | I17: 32500 | J17: 7000 | K17: 0 | R17: -132000 | T17: =SUM(B17:S17) -> 560000
A18: 12th | B18: 211500 | C18: 24000 | D18: 122400 | E18: 19000 | F18: 107000 | H18: 29000 | I18: 32000 | J18: 3000 | K18: 0 | R18: 2000 | T18: =SUM(B18:S18) -> 549900
A19: 13th | B19: 209500 | C19: 65000 | D19: 89500 | E19: 4500 | F19: 82500 | H19: 56000 | I19: 83500 | J19: 2000 | K19: 0 | R19: 323000 | T19: =SUM(B19:S19) -> 915500
A20: 14th | B20: 237500 | C20: 26000 | D20: 55000 | E20: 2500 | F20: 109100 | G20: 12000 | H20: 30000 | I20: 49000 | J20: 5000 | K20: 0 | O20: 46000 | R20: 20000 | T20: =SUM(B20:S20) -> 592100
A21: 15th | B21: 268000 | C21: 201000 | D21: 113000 | E21: 16500 | F21: 122500 | G21: 12000 | H21: 38000 | I21: 50000 | J21: 6000 | K21: 0 | O21: 12000 | R21: 7000 | T21: =SUM(B21:S21) -> 846000
A22: 16TH | B22: 210000 | C22: 176000 | D22: 126000 | E22: 8000 | F22: 121000 | H22: 92000 | I22: 93000 | J22: 23000 | K22: 0 | O22: 6000 | T22: =SUM(B22:S22) -> 855000
A23: 17th | B23: 277000 | C23: 253000 | D23: 69000 | E23: 8000 | F23: 143000 | G23: 6000 | H23: 65000 | I23: 17000 | J23: 31000 | K23: 0 | O23: 44000 | R23: 420000 | T23: =SUM(B23:S23) -> 1333000
A24: 18th | B24: 221500 | C24: 178000 | D24: 108500 | E24: 26000 | F24: 127000 | G24: 12000 | H24: 103000 | I24: 105000 | J24: 10000 | K24: 0 | O24: 12000 | R24: 30000 | T24: =SUM(B24:S24) -> 933000
A25: 19th | B25: 194500 | C25: 39000 | D25: 140000 | E25: 15000 | F25: 148000 | G25: 6000 | H25: 160000 | I25: 64500 | J25: 45000 | K25: 0 | O25: 6000 | R25: -120000 | T25: =SUM(B25:S25) -> 698000
A26: 20th | B26: 224500 | C26: 107000 | D26: 158000 | E26: 11000 | F26: 131500 | H26: 50000 | I26: 54000 | J26: 22000 | K26: 0 | O26: 6000 | R26: 2783000 | T26: =SUM(B26:S26) -> 3547000 | U26: 2000000
A27: 21st | B27: 223500 | C27: 271000 | D27: 147500 | E27: 32500 | F27: 100000 | H27: 82000 | I27: 118500 | J27: 5000 | K27: 0 | O27: 26000 | R27: -106000 | T27: =SUM(B27:S27) -> 900000
A28: 22nd | B28: 188000 | C28: 68000 | D28: 152000 | E28: 4000 | F28: 171500 | H28: 124500 | I28: 14000 | J28: 36000 | K28: 0 | O28: 30000 | R28: -78000 | T28: =SUM(B28:S28) -> 710000
A29: 23rd | B29: 388000 | C29: 327000 | D29: 243500 | E29: 16500 | F29: 209000 | H29: 229000 | I29: 172000 | J29: 27500 | K29: 0 | O29: 12000 | R29: -630000 | T29: =SUM(B29:S29) -> 994500
A30: 24th | B30: 445500 | C30: 609000 | D30: 238000 | E30: 99000 | F30: 360700 | G30: 6000 | H30: 454000 | I30: 282000 | J30: 32000 | K30: 0 | O30: 36000 | R30: -143500 | T30: =SUM(B30:S30) -> 2418700
A31: 25th | B31: 266000 | C31: 61000 | D31: 112000 | E31: 12500 | F31: 181000 | H31: 155000 | I31: 42500 | J31: 9000 | K31: 0 | O31: 34000 | T31: =SUM(B31:S31) -> 873000
A32: 26th | B32: 314500 | C32: 193000 | D32: 128000 | E32: 24000 | F32: 337000 | G32: 12000 | H32: 56000 | I32: 46500 | J32: 9000 | K32: 0 | O32: 48000 | T32: =SUM(B32:S32) -> 1168000
A33: 27th | B33: 178000 | C33: 171000 | D33: 104000 | E33: 10500 | F33: 184000 | H33: 102000 | I33: 27500 | J33: 8000 | K33: 0 | O33: 44000 | T33: =SUM(B33:S33) -> 829000
A34: 28th | B34: 256000 | C34: 154000 | D34: 152500 | E34: 2000 | F34: 143000 | G34: 12000 | H34: 135000 | I34: 62000 | J34: 2000 | K34: 0 | O34: 32000 | T34: =SUM(B34:S34) -> 950500
A35: 29th | B35: 265000 | C35: 197000 | D35: 209000 | E35: 7000 | F35: 242000 | H35: 136000 | I35: 33000 | J35: 18000 | O35: 11000 | R35: 303000 | T35: =SUM(B35:S35) -> 1421000
A36: 30th | B36: 240500 | C36: 173000 | D36: 127000 | E36: 15000 | F36: 213500 | H36: 52000 | I36: 2000 | J36: 7000 | K36: 0 | O36: 68000 | R36: -82000 | T36: =SUM(B36:S36) -> 816000
A37: 31st | B37: 209000 | C37: 153000 | D37: 83500 | E37: 9500 | F37: 110400 | H37: 7500 | I37: 7000 | J37: 12000 | O37: 47000 | T37: =SUM(B37:S37) -> 638900
A38: GRAND TOTAL | B38: =SUM(B7:B37) -> 7338000 | C38: =SUM(C7:C37) -> 4654000 | D38: =SUM(D7:D37) -> 3865900 | E38: =SUM(E7:E37) -> 496000 | F38: =SUM(F7:F37) -> 4630000 | G38: =SUM(G7:G37) -> 126000 | H38: =SUM(H7:H37) -> 2724500 | I38: =SUM(I7:I37) -> 1923000 | ... T38: =SUM(T7:T37) -> 34624400

Sheet WEEKLY REPORT DEC 2023  
B3: TotalEnergies MARKETING UGANDA LIMITED
B4: SHOP WEEKLY REPORT (MTD)
B7: SHOP NAME | C7: TotalEnergies RWIZI
B9: DATE: | C9: 01.12.2023
B10: Product category | C10: Week 1 | D10: week 2 | E10: Week 3 | F10: Week 4 | G10: Week 5 | H10: TOTAL
B11: Non Alcholic | C11: 1443000 | D11: 1525500 | E11: 1619000 | F11: 2036000 | G11: 712500 | H11: =SUM(C11:G11) -> 7336000
B12: Alcoholic | C12: 760000 | D12: 563000 | E12: 1225000 | F12: 1583000 | G12: 523000 | H12: =SUM(C12:G12) -> 4654000
B13: Fresh Products | C13: 726500 | D13: 727900 | E13: 862000 | F13: 1130000 | G13: 419500 | H13: =SUM(C13:G13) -> 3865900
B14: Ice creams | C14: 95000 | D14: 84000 | E14: 117000 | F14: 173500 | G14: 20700 | H14: =SUM(C14:G14) -> 490200
B15: Confectionery | C15: 760100 | D15: 825100 | E15: 893000 | F15: 1585700 | G15: 565900 | H15: =SUM(C15:G15) -> 4629800
B16: Tobacco | C16: 24000 | D16: 36000 | E16: 36000 | F16: 28000 | G16: 0 | H16: =SUM(C16:G16) -> 124000
B17: Grocery | C17: 360500 | D17: 323000 | E17: 590000 | F17: 1255500 | G17: 195500 | H17: =SUM(C17:G17) -> 2724500
